### Java

1. 예외처리에 대한 학습

   - try - catch - finally

   - (Runtime)Exception을 상속받는 FoolException을 throw 하는 법.

     ```java
     public class FoolException extends Exception {
     }
     ```

     ```java
     public class ExceptionTest {
     	public void sayNick(String nick) {
     		try {
     			if ("fool".equals(nick)) {
     				throw new FoolException();
     			}
     		} catch (FoolException e) {
     			System.out.println("foolException이 발생.");
     		} finally {
     			System.out.println("이름은" + nick + "입니다.");
     		}
     
     	}
     
     	public static void main(String[] args) {
     		ExceptionTest test = new ExceptionTest();
     		test.sayNick("fool");
     		test.sayNick("john");
     	}
     	//다음을 출력.
     	/* 
     	 * foolException이 발생.
     	 * 이름은 fool입니다.
     	 * 이름은 john입니다. 
     	*/
     }
     ```

     -> try해서 catch의 인자에 해당하는 예외가 발생하면 finally 구문을 실행.

     -> FoolException이 RuntimeException과 같은 종류의 예외를 발생시킬 때와,
     일반 Exception을 발생시킬 때는 다르게 쓰임.

     - Exception은 checked Exception이고 RuntimeException은 unchecked Exception임. 이 때 checked는 '예상 가능한'이라는 의미를 가지고 있음. 실행 도중 인터넷 연결이 끊기는 사태는 예상 가능한 것으로 취급. 반면 메모리가 부족한 것과 같은 상황은 예상 불가능한 예외로 취급.
     - ![exception-handling-exception-hierarchy_html](C:\Users\User\Desktop\TodayILearned\img\exception-handling-exception-hierarchy_html.png)

     사진출처 : [http://www.javamadesoeasy.com/2015/05/exception-handling-exception-hierarchy.html]

     - 위의 사진을 보면 무엇이 예측 가능하고 무엇이 예측 불가능한지 나와 있음. 예측 불가능한 예외는 try-catch문을 쓰지 않아도 throw할 수 있는 반면 예측 가능한 예외는 try-catch문 없이 throw할 경우 컴파일 에러가 발생. 컴파일 에러가 예측 가능한 예외를 throw할 경우에만 일어나는 것은 checked Exception은 컴파일 시에 예외를 확인하고 예외 발생 시 로직에 따라 추가적으로 프로그래머가 처리할 수 있는 반면, 예측불가능한 예외는 어차피 프로그래머가 할 수 있는 게 없으니 그냥 상위 caller로 던져버려라는 식으로 해석할 수 있기 때문임. 그러나 아직 이에 대해서는 제대로된 파악이 되지 않으니 여기에 대한 추가적인 학습이 필요할 듯.

   - throws - 메소드에서 throw시켜 상위 콜러에서 에러를 처리하도록 만듦.

     ```java 
     public class ExceptionThrowTest {
         //아래에서 throws
     	public void sayNick(String nick) throws FoolException {
     
     		if ("fool".equals(nick)) {
     			throw new FoolException();
     		}
     		System.out.println(nick);
     	}
     
     	public static void main(String[] args) {
     		ExceptionThrowTest test = new ExceptionThrowTest();
     		try {
     			test.sayNick("fool");
     			test.sayNick("john");
     		} catch (FoolException e) {
     			System.out.println("foolexception 발생");
     		}
     		//foolexception 발생이 출력됨.
     	}
     }
     
     ```

     -> 예외를 상위 caller로 던짐. 따라서 예외에 대한 처리를 상위 caller 에서 해야 함.

     -> sayNick 메소드에서 처리하는 경우 sayNick("fool")에서 예외가 발생해도 sayNick("john")을 수행함. 그러나 main메소드에서 처리하는 경우 test.sayNick("fool")에서 예외가 발생하면 sayNick("john")은 수행하지 않음. 이는 다음 번에 학습할 '트랜잭션'과도 관련 있는 개념임.